<?xml version="1.0" ?>
<sdf version="1.10">
    <world name="WorldR">
        <physics name="1ms" type="ignored">
            <max_step_size>0.001</max_step_size>
            <real_time_factor>1.0</real_time_factor>
        </physics>
        <plugin
            filename="gz-sim-physics-system"
            name="gz::sim::systems::Physics">
        </plugin>
        <plugin
            filename="gz-sim-user-commands-system"
            name="gz::sim::systems::UserCommands">
        </plugin>
        <plugin
            filename="gz-sim-scene-broadcaster-system"
            name="gz::sim::systems::SceneBroadcaster">
        </plugin>

        <gravity>0 0 0</gravity>

        <!--light type="directional" name="sun">
            <cast_shadows>true</cast_shadows>
            <pose>0 0 10 0 0 0</pose>
            <diffuse>0.8 0.8 0.8 1</diffuse>
            <specular>0.2 0.2 0.2 1</specular>
            <attenuation>
                <range>1000</range>
                <constant>0.9</constant>
                <linear>0.01</linear>
                <quadratic>0.001</quadratic>
            </attenuation>
            <direction>-0.5 0.1 -0.9</direction>
        </light-->
        
        <light type="point" name="omni_light">
            <pose>0 0 10 0 0 0</pose> <!-- Ubicación en el espacio -->
            <diffuse>1 1 1 1</diffuse>
            <specular>0.2 0.2 0.2 1</specular>
            <attenuation>
                <range>100</range>
                <constant>0.5</constant>
                <linear>0.01</linear>
                <quadratic>0.001</quadratic>
            </attenuation>
        </light>


        <model name="ground_plane">
            <static>true</static>
            <link name="link">
                <collision name="collision">
                <geometry>
                    <plane>
                    <normal>0 0 1</normal>
                    </plane>
                </geometry>
                </collision>
                <visual name="visual">
                <geometry>
                    <plane>
                    <normal>0 0 1</normal>
                    <size>100 100</size>
                    </plane>
                </geometry>
                <material>
                    <ambient>0.8 0.8 0.8 1</ambient>
                    <diffuse>0.8 0.8 0.8 1</diffuse>
                    <specular>0.8 0.8 0.8 1</specular>
                </material>
                </visual>
            </link>
        </model>

        <model name='robot' canonical_link='link1'>
            <pose relative_to='world'>0 0 0 0 0 0</pose>

            <link name="link1">
                <pose relative_to='__model__'>0 0 0 0 0 0</pose>

                <visual name='visual1'>
                <geometry>
                    <mesh>
                        <uri>/home/oswaldo/Ros2WS/src/robot/robot/meshes/link1.stl</uri>
                        <scale>0.01 0.01 0.01</scale>
                    </mesh>
                </geometry>
                <material>
                    <ambient>0.5 0.5 0.5 1</ambient>
                    <diffuse>0.5 0.5 0.5 1</diffuse>
                    <specular>0.1 0.1 0.1 1</specular>
                </material>
                </visual>

                <collision name='collision'>
                    <geometry>
                        <mesh>
                            <uri>/home/oswaldo/Ros2WS/src/robot/robot/meshes/link1.stl</uri>
                            <scale>0.01 0.01 0.01</scale>
                        </mesh>
                    </geometry>
                </collision>
            </link>


            <link name='link2'>
                <pose relative_to="link1">0.15 0 0.36 0 0 0</pose>

                <visual name='visual2'>

                <origin xyz="0 0 0" rpy="0 0 0"/>
                <geometry>
                    <mesh>
                        <uri>/home/oswaldo/Ros2WS/src/robot/robot/meshes/link2.stl</uri>
                        <scale>0.01 0.01 0.01</scale>
                    </mesh>
                </geometry>
                <material>
                    <ambient>0.5 0.5 0.5 1</ambient>
                    <diffuse>0.5 0.5 0.5 1</diffuse>
                    <specular>0.1 0.1 0.1 1</specular>
                </material>
                </visual>

                <collision name='collision'>
                    <geometry>
                        <mesh>
                            <uri>/home/oswaldo/Ros2WS/src/robot/robot/meshes/link2.stl</uri>
                            <scale>0.01 0.01 0.01</scale>
                        </mesh>
                    </geometry>
                </collision>
            </link>

            <link name='link3'>
                <pose relative_to="link2">0 0 0.4 0 0 0</pose>

                <visual name='visual3'>

                <origin xyz="0 0 0" rpy="0 0 0"/>
                <geometry>
                    <mesh>
                        <uri>/home/oswaldo/Ros2WS/src/robot/robot/meshes/link3.stl</uri>
                        <scale>0.01 0.01 0.01</scale>
                    </mesh>
                </geometry>
                <material>
                    <ambient>0.5 0.5 0.5 1</ambient>
                    <diffuse>0.5 0.5 0.5 1</diffuse>
                    <specular>0.1 0.1 0.1 1</specular>
                </material>
                </visual>

                <collision name='collision'>
                    <geometry>
                        <mesh>
                            <uri>/home/oswaldo/Ros2WS/src/robot/robot/meshes/link3.stl</uri>
                            <scale>0.01 0.01 0.01</scale>
                        </mesh>
                    </geometry>
                </collision>
            </link>

            <link name='link4'>
                <pose relative_to="link3">0.25 0 1.278 0 0 0</pose>

                <visual name='visual4'>

                <origin xyz="0 0 0" rpy="0 0 0"/>
                <geometry>
                    <mesh>
                        <uri>/home/oswaldo/Ros2WS/src/robot/robot/meshes/link4.stl</uri>
                        <scale>0.01 0.01 0.01</scale>
                    </mesh>
                </geometry>
                <material>
                    <ambient>0.5 0.5 0.5 1</ambient>
                    <diffuse>0.5 0.5 0.5 1</diffuse>
                    <specular>0.1 0.1 0.1 1</specular>
                </material>
                </visual>

                <collision name='collision'>
                    <geometry>
                        <mesh>
                            <uri>/home/oswaldo/Ros2WS/src/robot/robot/meshes/link4.stl</uri>
                            <scale>0.01 0.01 0.01</scale>
                        </mesh>
                    </geometry>
                </collision>
            </link>

            <link name='link5'>
                <pose relative_to="link4">1.24 0 0 0 0 0</pose>

                <visual name='visual5'>

                <origin xyz="0 0 0" rpy="0 0 0"/>
                <geometry>
                    <mesh>
                        <uri>/home/oswaldo/Ros2WS/src/robot/robot/meshes/link5.stl</uri>
                        <scale>0.01 0.01 0.01</scale>
                    </mesh>
                </geometry>
                <material>
                    <ambient>0.5 0.5 0.5 1</ambient>
                    <diffuse>0.5 0.5 0.5 1</diffuse>
                    <specular>0.1 0.1 0.1 1</specular>
                </material>
                </visual>

                <collision name='collision'>
                    <geometry>
                        <mesh>
                            <uri>/home/oswaldo/Ros2WS/src/robot/robot/meshes/link5.stl</uri>
                            <scale>0.01 0.01 0.01</scale>
                        </mesh>
                    </geometry>
                </collision>
            </link>
        
            <link name='GripperRight'>
                <pose relative_to="link5">0.83 -0.3 0 0 0 0</pose>

                <visual name='visual6'>

                <origin xyz="0 0 0" rpy="0 0 0"/>
                <geometry>
                    <mesh>
                        <uri>/home/oswaldo/Ros2WS/src/robot/robot/meshes/gripper_right_palm.stl</uri>
                        <scale>0.01 0.01 0.01</scale>
                    </mesh>
                </geometry>
                <material>
                    <ambient>0.5 0.5 0.5 1</ambient>
                    <diffuse>0.5 0.5 0.5 1</diffuse>
                    <specular>0.1 0.1 0.1 1</specular>
                </material>
                </visual>

                <collision name='collision'>
                    <geometry>
                        <mesh>
                            <uri>/home/oswaldo/Ros2WS/src/robot/robot/meshes/gripper_right_palm.stl</uri>
                            <scale>0.01 0.01 0.01</scale>
                        </mesh>
                    </geometry>
                </collision>
            </link>

            <link name='GripperLeft'>
                <pose relative_to="link5">0.83 0.3 0 0 0 0</pose>

                <visual name='visual7'>

                <origin xyz="0 0 0" rpy="0 0 0"/>
                <geometry>
                    <mesh>
                        <uri>/home/oswaldo/Ros2WS/src/robot/robot/meshes/gripper_left_palm.stl</uri>
                        <scale>0.01 0.01 0.01</scale>
                    </mesh>
                </geometry>
                <material>
                    <ambient>0.5 0.5 0.5 1</ambient>
                    <diffuse>0.5 0.5 0.5 1</diffuse>
                    <specular>0.1 0.1 0.1 1</specular>
                </material>
                </visual>

                <collision name='collision'>
                    <geometry>
                        <mesh>
                            <uri>/home/oswaldo/Ros2WS/src/robot/robot/meshes/gripper_left_palm.stl</uri>
                            <scale>0.01 0.01 0.01</scale>
                        </mesh>
                    </geometry>
                </collision>
            </link>

            <joint name='World-link1' type='fixed'>
                <pose relative_to='link2'/>
                <parent>world</parent>
                <child>link1</child>
            </joint>            

            <joint name='link1-2' type='revolute'>
                <pose relative_to='link2'/>
                <parent>link1</parent>
                <child>link2</child>
                <axis>
                    <xyz expressed_in='__model__'>0 0 1</xyz> <!--can be defined as any frame or even arbitrary frames-->
                    <limit>
                        <lower>-1.79769e+308</lower>    <!--negative infinity-->
                        <upper>1.79769e+308</upper>     <!--positive infinity-->
                    </limit>
                </axis>
            </joint>

            <joint name='link2-3' type='revolute'>
                <pose relative_to='link3'/>
                <parent>link2</parent>
                <child>link3</child>
                <axis>
                    <xyz expressed_in='__model__'>0 1 0</xyz> <!--can be defined as any frame or even arbitrary frames-->
                    <limit>
                        <lower>-1.79769e+308</lower>    <!--negative infinity-->
                        <upper>1.79769e+308</upper>     <!--positive infinity-->
                    </limit>
                </axis>
            </joint>

            <joint name='link3-4' type='revolute'>
                <pose relative_to='link4'/>
                <parent>link3</parent>
                <child>link4</child>
                <axis>
                    <xyz expressed_in='__model__'>0 1 0</xyz> <!--can be defined as any frame or even arbitrary frames-->
                    <limit>
                        <lower>-1.79769e+308</lower>    <!--negative infinity-->
                        <upper>1.79769e+308</upper>     <!--positive infinity-->
                    </limit>
                </axis>
            </joint>

            <joint name='link4-5' type='revolute'>
                <pose relative_to='link5'/>
                <parent>link4</parent>
                <child>link5</child>
                <axis>
                    <xyz expressed_in='__model__'>0 1 0</xyz> <!--can be defined as any frame or even arbitrary frames-->
                    <limit>
                        <lower>-1.79769e+308</lower>    <!--negative infinity-->
                        <upper>1.79769e+308</upper>     <!--positive infinity-->
                    </limit>
                </axis>
            </joint>

            <joint name='GripperRight-5' type='prismatic'>
                <pose relative_to='GripperRight'/>
                <parent>link5</parent>
                <child>GripperRight</child>
                <axis>
                    <xyz expressed_in='__model__'>0 1 0</xyz> <!--can be defined as any frame or even arbitrary frames-->
                    <limit>
                        <lower>-1.79769e+308</lower>    <!--negative infinity-->
                        <upper>1.79769e+308</upper>     <!--positive infinity-->
                    </limit>
                </axis>
            </joint>

            <joint name='GripperLeft-5' type='prismatic'>
                <pose relative_to='GripperLeft'/>
                <parent>link5</parent>
                <child>GripperLeft</child>
                <axis>
                    <xyz expressed_in='__model__'>0 1 0</xyz> <!--can be defined as any frame or even arbitrary frames-->
                    <limit>
                        <lower>-1.79769e+308</lower>    <!--negative infinity-->
                        <upper>1.79769e+308</upper>     <!--positive infinity-->
                    </limit>
                </axis>
            </joint>

            <plugin
                filename="gz-sim-joint-position-controller-system"
                name="gz::sim::systems::JointPositionController">
                <joint_name>link1-2</joint_name>
                <topic>/J1</topic>
                <p_gain>100</p_gain>
                <i_gain>1</i_gain>
                <d_gain>80</d_gain>
                <i_max>10</i_max>
                <i_min>-10</i_min>
                <cmd_max>10</cmd_max>
                <cmd_min>-10</cmd_min>
            </plugin>

            <plugin
                filename="gz-sim-joint-position-controller-system"
                name="gz::sim::systems::JointPositionController">
                <joint_name>link2-3</joint_name>
                <topic>/J2</topic>
                <p_gain>100</p_gain>
                <i_gain>1</i_gain>
                <d_gain>80</d_gain>
                <i_max>10</i_max>
                <i_min>-10</i_min>
                <cmd_max>10</cmd_max>
                <cmd_min>-10</cmd_min>
            </plugin>

            <plugin
                filename="gz-sim-joint-position-controller-system"
                name="gz::sim::systems::JointPositionController">
                <joint_name>link3-4</joint_name>
                <topic>/J3</topic>
                <p_gain>100</p_gain>
                <i_gain>1</i_gain>
                <d_gain>80</d_gain>
                <i_max>10</i_max>
                <i_min>-10</i_min>
                <cmd_max>10</cmd_max>
                <cmd_min>-10</cmd_min>
            </plugin>

            <plugin
                filename="gz-sim-joint-position-controller-system"
                name="gz::sim::systems::JointPositionController">
                <joint_name>link4-5</joint_name>
                <topic>/J4</topic>
                <p_gain>100</p_gain>
                <i_gain>1</i_gain>
                <d_gain>80</d_gain>
                <i_max>10</i_max>
                <i_min>-10</i_min>
                <cmd_max>10</cmd_max>
                <cmd_min>-10</cmd_min>
            </plugin>

            <plugin
                filename="gz-sim-joint-position-controller-system"
                name="gz::sim::systems::JointPositionController">
                <joint_name>GripperRight-5</joint_name>
                <topic>/J5</topic>
                <p_gain>100</p_gain>
                <i_gain>1</i_gain>
                <d_gain>80</d_gain>
                <i_max>10</i_max>
                <i_min>-10</i_min>
                <cmd_max>10</cmd_max>
                <cmd_min>-10</cmd_min>
            </plugin>

            <plugin
                filename="gz-sim-joint-position-controller-system"
                name="gz::sim::systems::JointPositionController">
                <joint_name>GripperLeft-5</joint_name>
                <topic>/J6</topic>
                <p_gain>100</p_gain>
                <i_gain>1</i_gain>
                <d_gain>80</d_gain>
                <i_max>10</i_max>
                <i_min>-10</i_min>
                <cmd_max>10</cmd_max>
                <cmd_min>-10</cmd_min>
            </plugin>

        </model>
    </world>
</sdf>