<?xml version="1.0" ?>
<sdf version="1.10">
    <world name="car_world">
        <physics name="1ms" type="ignored">
            <max_step_size>0.001</max_step_size>
            <real_time_factor>1.0</real_time_factor>
        </physics>
        <plugin
            filename="gz-sim-physics-system"
            name="gz::sim::systems::Physics">
        </plugin>
        <plugin
            filename="gz-sim-user-commands-system"
            name="gz::sim::systems::UserCommands">
        </plugin>
        <plugin
            filename="gz-sim-scene-broadcaster-system"
            name="gz::sim::systems::SceneBroadcaster">
        </plugin>

        <light type="directional" name="sun">
            <cast_shadows>true</cast_shadows>
            <pose>0 0 10 0 0 0</pose>
            <diffuse>0.8 0.8 0.8 1</diffuse>
            <specular>0.2 0.2 0.2 1</specular>
            <attenuation>
                <range>1000</range>
                <constant>0.9</constant>
                <linear>0.01</linear>
                <quadratic>0.001</quadratic>
            </attenuation>
            <direction>-0.5 0.1 -0.9</direction>
        </light>

        <model name='open_manipulator_x'>
            <joint name='world_fixed' type='fixed'>
            <pose relative_to='__model__'>0 0 0 0 0 0</pose>
            <parent>world</parent>
            <child>link1</child>
            </joint>
            <link name='link1'>
            <pose relative_to='world_fixed'>0 0 0 0 0 0</pose>
            <inertial>
                <pose>0.00030876154000000002 0 -0.00012176461 0 0 0</pose>
                <mass>0.079119962000000002</mass>
                <inertia>
                <ixx>1.2505234e-05</ixx>
                <ixy>0</ixy>
                <ixz>-1.7855208e-07</ixz>
                <iyy>2.1898363999999998e-05</iyy>
                <iyz>0</iyz>
                <izz>1.9267361000000001e-05</izz>
                </inertia>
            </inertial>
            <collision name='link1_collision'>
                <pose>0 0 0 0 0 0</pose>
                <geometry>
                <mesh uri="meshes/link1.stl"/>
                </geometry>
            </collision>
            <visual name='link1_visual'>
                <pose>0 0 0 0 0 0</pose>
                <geometry>
                <mesh uri="meshes/link1.stl"/>
                </geometry>
            </visual>
            </link>
            <joint name='joint1' type='revolute'>
            <parent>link1</parent>
            <pose relative_to='link1'>0.012 0 0.017000000000000001 0 0 0</pose>
            <axis>
                <xyz>0 0 1</xyz>
                <limit>
                <lower>-3.1415999999999999</lower>
                <upper>3.1415999999999999</upper>
                <effort>1</effort>
                <velocity>4.7999999999999998</velocity>
                </limit>
                <dynamics>
                <damping>0.10000000000000001</damping>
                <friction>0</friction>
                <spring_reference>0</spring_reference>
                <spring_stiffness>0</spring_stiffness>
                </dynamics>
            </axis>
            </joint>
        </model>
    </world>
</sdf>