<?xml version="1.0" ?>
<sdf version="1.10">
    <world name="Robot digital twin">
        <physics name="1ms" type="ignored">
            <max_step_size>0.001</max_step_size>
            <real_time_factor>1.0</real_time_factor>
        </physics>
        <plugin
            filename="gz-sim-physics-system"
            name="gz::sim::systems::Physics">
        </plugin>
        <plugin
            filename="gz-sim-user-commands-system"
            name="gz::sim::systems::UserCommands">
        </plugin>
        <plugin
            filename="gz-sim-scene-broadcaster-system"
            name="gz::sim::systems::SceneBroadcaster">
        </plugin>

        <light type="directional" name="sun">
            <cast_shadows>true</cast_shadows>
            <pose>0 0 10 0 0 0</pose>
            <diffuse>0.8 0.8 0.8 1</diffuse>
            <specular>0.2 0.2 0.2 1</specular>
            <attenuation>
                <range>1000</range>
                <constant>0.9</constant>
                <linear>0.01</linear>
                <quadratic>0.001</quadratic>
            </attenuation>
            <direction>-0.5 0.1 -0.9</direction>
        </light>

        <model name="ground_plane">
            <static>true</static>
            <link name="link">
                <collision name="collision">
                <geometry>
                    <plane>
                    <normal>0 0 1</normal>
                    </plane>
                </geometry>
                </collision>
                <visual name="visual">
                <geometry>
                    <plane>
                    <normal>0 0 1</normal>
                    <size>100 100</size>
                    </plane>
                </geometry>
                <material>
                    <ambient>0.8 0.8 0.8 1</ambient>
                    <diffuse>0.8 0.8 0.8 1</diffuse>
                    <specular>0.8 0.8 0.8 1</specular>
                </material>
                </visual>
            </link>
        </model>

        <model name='open_manipulator_x'>
          <joint name='world_fixed' type='fixed'>
            <pose relative_to='__model__'>0 0 0 0 0 0</pose>
            <parent>world</parent>
            <child>link1</child>
          </joint>
          <link name='link1'>
            <pose relative_to='world_fixed'>0 0 0 0 0 0</pose>
            <inertial>
              <pose>0.00030876154000000002 0 -0.00012176461 0 0 0</pose>
              <mass>0.079119962000000002</mass>
              <inertia>
                <ixx>1.2505234e-05</ixx>
                <ixy>0</ixy>
                <ixz>-1.7855208e-07</ixz>
                <iyy>2.1898363999999998e-05</iyy>
                <iyz>0</iyz>
                <izz>1.9267361000000001e-05</izz>
              </inertia>
            </inertial>
            <collision name='link1_collision'>
              <pose>0 0 0 0 0 0</pose>
              <geometry>
                <mesh>
                  <scale>0.001 0.001 0.001</scale>
                  <uri>../meshes/link1.stl</uri>
                </mesh>
              </geometry>
            </collision>
            <visual name='link1_visual'>
              <pose>0 0 0 0 0 0</pose>
              <geometry>
                <mesh>
                  <scale>0.001 0.001 0.001</scale>
                  <uri>../meshes/link1.stl</uri>
                </mesh>
              </geometry>
            </visual>
          </link>
          <joint name='joint1' type='revolute'>
            <pose relative_to='link1'>0.012 0 0.017 0 0 0</pose>
            <parent>link1</parent>
            <child>link2</child>
            <axis>
              <xyz>0 0 1</xyz>
              <limit>
                <lower>-3.1416</lower>
                <upper>3.1416</upper>
                <effort>1</effort>
                <velocity>4.8</velocity>
              </limit>
              <dynamics>
                <damping>0.10000000000000001</damping>
                <friction>0</friction>
                <spring_reference>0</spring_reference>
                <spring_stiffness>0</spring_stiffness>
              </dynamics>
            </axis>
          </joint>
          <link name='link2'>
            <pose relative_to='joint1'>0 0 0 0 0 0</pose>
            <inertial>
              <pose>-0.00030184869999999998 0.00054043684000000005 0.047433464000000002 0 0 0</pose>
              <mass>0.098406836999999997</mass>
              <inertia>
                <ixx>3.4543421999999999e-05</ixx>
                <ixy>-1.6031095e-08</ixy>
                <ixz>-3.8375154999999999e-07</ixz>
                <iyy>3.2689328999999998e-05</iyy>
                <iyz>2.8511935e-08</iyz>
                <izz>1.8850319999999999e-05</izz>
              </inertia>
            </inertial>
            <collision name='link2_collision'>
              <pose>0 0 0.019 0 0 0</pose>
              <geometry>
                <mesh>
                  <scale>0.001 0.001 0.001</scale>
                  <uri>../meshes/link2.stl</uri>
                </mesh>
              </geometry>
            </collision>
            <visual name='link2_visual'>
              <pose>0 0 0.019 0 0 0</pose>
              <geometry>
                <mesh>
                  <scale>0.001 0.001 0.001</scale>
                  <uri>../meshes/link2.stl</uri>
                </mesh>
              </geometry>
            </visual>
          </link>
          <joint name='joint2' type='revolute'>
            <pose relative_to='link2'>0 0 0.059499999999999997 0 0 0</pose>
            <parent>link2</parent>
            <child>link3</child>
            <axis>
              <xyz>0 1 0</xyz>
              <limit>
                <lower>-1.5</lower>
                <upper>1.5</upper>
                <effort>1</effort>
                <velocity>4.7999999999999998</velocity>
              </limit>
              <dynamics>
                <damping>0.10000000000000001</damping>
                <friction>0</friction>
                <spring_reference>0</spring_reference>
                <spring_stiffness>0</spring_stiffness>
              </dynamics>
            </axis>
          </joint>
          <link name='link3'>
            <pose relative_to='joint2'>0 0 0 0 0 0</pose>
            <inertial>
              <pose>0.010308393000000001 0.00037743363000000002 0.10170197 0 0 0</pose>
              <mass>0.13850916999999999</mass>
              <inertia>
                <ixx>0.00033055380999999999</ixx>
                <ixy>-9.7940978000000003e-08</ixy>
                <ixz>-3.8505711000000003e-05</ixz>
                <iyy>0.00034290447000000001</iyy>
                <iyz>-1.5717515999999999e-06</iyz>
                <izz>6.0346497999999997e-05</izz>
              </inertia>
            </inertial>
            <collision name='link3_collision'>
              <pose>0 0 0 0 0 0</pose>
              <geometry>
                <mesh>
                  <scale>0.001 0.001 0.001</scale>
                  <uri>../meshes/link3.stl</uri>
                </mesh>
              </geometry>
            </collision>
            <visual name='link3_visual'>
              <pose>0 0 0 0 0 0</pose>
              <geometry>
                <mesh>
                  <scale>0.001 0.001 0.001</scale>
                  <uri>../meshes/link3.stl</uri>
                </mesh>
              </geometry>
            </visual>
          </link>
          <joint name='joint3' type='revolute'>
            <pose relative_to='link3'>0.024 0 0.128 0 0 0</pose>
            <parent>link3</parent>
            <child>link4</child>
            <axis>
              <xyz>0 1 0</xyz>
              <limit>
                <lower>-1.5</lower>
                <upper>1.3999999999999999</upper>
                <effort>1</effort>
                <velocity>4.7999999999999998</velocity>
              </limit>
              <dynamics>
                <damping>0.10000000000000001</damping>
                <friction>0</friction>
                <spring_reference>0</spring_reference>
                <spring_stiffness>0</spring_stiffness>
              </dynamics>
            </axis>
          </joint>
          <link name='link4'>
            <pose relative_to='joint3'>0 0 0 0 0 0</pose>
            <inertial>
              <pose>0.090909589999999998 0.00038929816000000001 0.00022413279 0 0 0</pose>
              <mass>0.13274562000000001</mass>
              <inertia>
                <ixx>3.0654178000000002e-05</ixx>
                <ixy>-1.2764155000000001e-06</ixy>
                <ixz>-2.6874417e-07</ixz>
                <iyy>0.00024230292</iyy>
                <iyz>1.1559549999999999e-08</iyz>
                <izz>0.00025155057000000001</izz>
              </inertia>
            </inertial>
            <collision name='link4_collision'>
              <pose>0 0 0 0 0 0</pose>
              <geometry>
                <mesh>
                  <scale>0.001 0.001 0.001</scale>
                  <uri>../meshes/link4.stl</uri>
                </mesh>
              </geometry>
            </collision>
            <visual name='link4_visual'>
              <pose>0 0 0 0 0 0</pose>
              <geometry>
                <mesh>
                  <scale>0.001 0.001 0.001</scale>
                  <uri>../meshes/link4.stl</uri>
                </mesh>
              </geometry>
            </visual>
          </link>
          <joint name='joint4' type='revolute'>
            <pose relative_to='link4'>0.124 0 0 0 0 0</pose>
            <parent>link4</parent>
            <child>link5</child>
            <axis>
              <xyz>0 1 0</xyz>
              <limit>
                <lower>-1.7</lower>
                <upper>1.97</upper>
                <effort>1</effort>
                <velocity>4.7999999999999998</velocity>
              </limit>
              <dynamics>
                <damping>0.10000000000000001</damping>
                <friction>0</friction>
                <spring_reference>0</spring_reference>
                <spring_stiffness>0</spring_stiffness>
              </dynamics>
            </axis>
          </joint>
          <link name='link5'>
            <pose relative_to='joint4'>0 0 0 0 0 0</pose>
            <inertial>
              <pose>0.044206755 3.6839998499999999e-07 0.0089142215999999993 0 0 0</pose>
              <mass>0.14327572999999999</mass>
              <inertia>
                <ixx>8.0870749000000006e-05</ixx>
                <ixy>0</ixy>
                <ixz>-1.0157896000000001e-06</ixz>
                <iyy>7.5980465e-05</iyy>
                <iyz>0</iyz>
                <izz>9.3127350999999998e-05</izz>
              </inertia>
            </inertial>
            <collision name='link5_collision'>
              <pose>0 0 0 0 0 0</pose>
              <geometry>
                <mesh>
                  <scale>0.001 0.001 0.001</scale>
                  <uri>../meshes/link5.stl</uri>
                </mesh>
              </geometry>
            </collision>
            <visual name='link5_visual'>
              <pose>0 0 0 0 0 0</pose>
              <geometry>
                <mesh>
                  <scale>0.001 0.001 0.001</scale>
                  <uri>../meshes/link5.stl</uri>
                </mesh>
              </geometry>
            </visual>
            <visual name='link5_fixed_joint_lump__end_effector_link_visual_1'>
              <pose>0.126 0 0 0 0 0</pose>
              <geometry>
                <box>
                  <size>0.01 0.01 0.01</size>
                </box>
              </geometry>
            </visual>
          </link>
          <joint name='gripper_left_joint' type='prismatic'>
            <pose relative_to='link5'>0.081699999999999995 0.021000000000000001 0 0 0 0</pose>
            <parent>link5</parent>
            <child>gripper_left_link</child>
            <axis>
              <xyz>0 1 0</xyz>
              <limit>
                <lower>-0.01</lower>
                <upper>0.019</upper>
                <effort>1</effort>
                <velocity>4.7999999999999998</velocity>
              </limit>
              <dynamics>
                <damping>0.10000000000000001</damping>
                <friction>0</friction>
                <spring_reference>0</spring_reference>
                <spring_stiffness>0</spring_stiffness>
              </dynamics>
            </axis>
          </joint>
          <link name='gripper_left_link'>
            <pose relative_to='gripper_left_joint'>0 0 0 0 0 0</pose>
            <inertial>
              <pose>0 0 0 0 0 0</pose>
              <mass>0.001</mass>
              <inertia>
                <ixx>9.9999999999999995e-07</ixx>
                <ixy>0</ixy>
                <ixz>0</ixz>
                <iyy>9.9999999999999995e-07</iyy>
                <iyz>0</iyz>
                <izz>9.9999999999999995e-07</izz>
              </inertia>
            </inertial>
            <collision name='gripper_left_link_collision'>
              <pose>0 0 0 0 0 0</pose>
              <geometry>
                <mesh>
                  <scale>0.001 0.001 0.001</scale>
                  <uri>../meshes/gripper_left_palm.stl</uri>
                </mesh>
              </geometry>
            </collision>
            <visual name='gripper_left_link_visual'>
              <pose>0 0 0 0 0 0</pose>
              <geometry>
                <mesh>
                  <scale>0.001 0.001 0.001</scale>
                  <uri>../meshes/gripper_left_palm.stl</uri>
                </mesh>
              </geometry>
            </visual>
          </link>
          <joint name='gripper_right_joint' type='prismatic'>
            <pose relative_to='link5'>0.081699999999999995 -0.021000000000000001 0 0 0 0</pose>
            <parent>link5</parent>
            <child>gripper_right_link</child>
            <axis>
              <xyz>0 -1 0</xyz>
              <mimic joint='gripper_left_joint'>
                <multiplier>1</multiplier>
                <offset>0</offset>
                <reference>0</reference>
              </mimic>
              <limit>
                <lower>-0.01</lower>
                <upper>0.019</upper>
                <effort>1</effort>
                <velocity>4.7999999999999998</velocity>
              </limit>
              <dynamics>
                <damping>0.10000000000000001</damping>
                <friction>0</friction>
                <spring_reference>0</spring_reference>
                <spring_stiffness>0</spring_stiffness>
              </dynamics>
            </axis>
          </joint>
          <link name='gripper_right_link'>
            <pose relative_to='gripper_right_joint'>0 0 0 0 0 0</pose>
            <inertial>
              <pose>0 0 0 0 0 0</pose>
              <mass>0.001</mass>
              <inertia>
                <ixx>9.9999999999999995e-07</ixx>
                <ixy>0</ixy>
                <ixz>0</ixz>
                <iyy>9.9999999999999995e-07</iyy>
                <iyz>0</iyz>
                <izz>9.9999999999999995e-07</izz>
              </inertia>
            </inertial>
            <collision name='gripper_right_link_collision'>
              <pose>0 0 0 0 0 0</pose>
              <geometry>
                <mesh>
                  <scale>0.001 0.001 0.001</scale>
                  <uri>../meshes/gripper_right_palm.stl</uri>
                </mesh>
              </geometry>
            </collision>
            <visual name='gripper_right_link_visual'>
              <pose>0 0 0 0 0 0</pose>
              <geometry>
                <mesh>
                  <scale>0.001 0.001 0.001</scale>
                  <uri>../meshes/gripper_right_palm.stl</uri>
                </mesh>
              </geometry>
            </visual>
          </link>
          <frame name='end_effector_joint' attached_to='link5'>
            <pose>0.126 0 0 0 0 0</pose>
          </frame>
          <frame name='end_effector_link' attached_to='end_effector_joint'>
            <pose>0 0 0 0 0 0</pose>
          </frame>
          <frame name='gripper_right_joint_mimic' attached_to='gripper_right_link'>
            <pose>0 0 0 0 0 0</pose>
          </frame>
          <frame name='dummy_mimic_fix' attached_to='gripper_right_joint_mimic'>
            <pose>0 0 0 0 0 0</pose>
          </frame>
        </model>

        <!-- Moving Forward-->
            <plugin filename="gz-sim-triggered-publisher-system"
                    name="gz::sim::systems::TriggeredPublisher">
                <input type="gz.msgs.Int32" topic="/keyboard/keypress">
                    <match field="data">16777235</match>
                </input>
                <output type="gz.msgs.Twist" topic="/cmd_vel">
                    linear: {x: 0.5}, angular: {z: 0.0}
                </output>
            </plugin>
    </world>
</sdf>